input.txt
limit sell 5 100.00
limit sell 10 110.50
limit sell 3 106.00
stop buy 3 105.00
market buy 3 0.00
stop sell 3 100.00
cancel na 1 0.00
market buy 4 0.00
market sell 4 0.00
limit buy 3 100
market sell 2 0.00
limit buy 5 105
limit buy 10 106
limit buy 4 101
market buy 2 100
stop sell 2 105
stop sell 2 102
limit sell 9 100
limit sell 5 100
